 // C++ program to handle
// exceptions
#include <iostream>

using namespace std;
 

int division(int a, int b)
{

  // Checking if the denominator 

  // is 0 or not.

  if (b == 0)

  {

    // If the denominator is 0, then 

    // we must throw an exception

    throw "Division by zero!";

  }

     

  // If there is no exception, then

  // we are returning the answer.

  return int(a / b);
}
 
// Driver code

int main()
{

  int x = 50;

  int y = 0;

  int answer = 0;

     

  /*

    Using a try catch block because in division, 

    the denominator can be 0. 

    So, we must handle the 0 division inside try block.

  */

  try

  {

    answer = division(x, y);

    cout << " Output: " << answer << endl;

  }

     

  // Printing the thrown exception from 

  // the function

  catch (const char *errorMessage)

  {

    cout << errorMessage << endl;

  }

   

  return 0;
}
